Workbook

Sheet Baza de date
A1: Nr.crt | B1: Produs | C1: Denumire grup | D1: Unitate masura | E1: Data de receptionate | F1: Data livrare | G1: Locul de depozitare | H1: Locatie | I1: Cantitate de produs | J1: Stare operatiuni | K1: Destinatie | L1: Pret receptie unitar/RON | M1: Cheltuieli | N1: Transport | O1: Cantitate Total kg | P1: Vandute kg/luna | Q1: Rest | R1: Vandute/RON | S1: Profit
A2: 1 | B2: Varza | C2: Alimente | D2: buc/kg | E2: 43904 | F2: 43905 | G2: D - A | H2: =IF(Таблица3[[#This Row],[Denumire grup]]=Ghid!$B$6,"A1 - A10",IF(Таблица3[[#This Row],[Denumire grup]]=Ghid!$B$5,"A11 - A20",IF(Таблица3[[#This Row],[Denumire grup]]=Ghid!$B$7,"B1 - B5",IF(Таблица3[[#This Row],[Denumire grup]]=Ghid!$B$8,"B6 - B15",IF(Таблица3[[#This Row],[Denumire grup]]=Ghid!$B$9,"B16 - B30",IF(Таблица3[[#This Row],[Denumire grup]]=Ghid!$B$10,"C1 - C20","C21 - C30")))))) -> A1 - A10 | I2: 10000 | J2: Retur | K2: Bucuresti | L2: 150 | M2: =Таблица3[[#This Row],[Pret receptie unitar/RON]]*Таблица3[[#This Row],[Cantitate de produs]] -> 1500000 | N2: Transport firma | O2: =Таблица3[[#This Row],[Cantitate de produs]]+20 -> 10020 | P2: 520 | Q2: =Таблица3[[#This Row],[Cantitate Total kg]]-Таблица3[[#This Row],[Vandute kg/luna]] -> 9500 | R2: =Таблица3[[#This Row],[Vandute kg/luna]]*(Таблица3[[#This Row],[Pret receptie unitar/RON]]+((Таблица3[[#This Row],[Pret receptie unitar/RON]]*25)/100)) -> 97500 | S2: =Таблица3[[#This Row],[Vandute/RON]]-Таблица3[[#This Row],[Cheltuieli]] -> -1402500
A3: =A2+1 -> 2 | B3: Rosie | C3: Alimente | D3: buc/kg | E3: 43966 | F3: 43998 | G3: D - A | H3: =IF(Таблица3[[#This Row],[Denumire grup]]=Ghid!$B$6,"A1 - A10",IF(Таблица3[[#This Row],[Denumire grup]]=Ghid!$B$5,"A11 - A20",IF(Таблица3[[#This Row],[Denumire grup]]=Ghid!$B$7,"B1 - B5",IF(Таблица3[[#This Row],[Denumire grup]]=Ghid!$B$8,"B6 - B15",IF(Таблица3[[#This Row],[Denumire grup]]=Ghid!$B$9,"B16 - B30",IF(Таблица3[[#This Row],[Denumire grup]]=Ghid!$B$10,"C1 - C20","C21 - C30")))))) -> A1 - A10 | I3: 800 | J3: Livrat | K3: Cluj - Napoca | L3: 200 | M3: =Таблица3[[#This Row],[Pret receptie unitar/RON]]*Таблица3[[#This Row],[Cantitate de produs]] -> 160000 | N3: Personal fizic | O3: =Таблица3[[#This Row],[Cantitate de produs]]+20 -> 820 | P3: 56 | Q3: =Таблица3[[#This Row],[Cantitate Total kg]]-Таблица3[[#This Row],[Vandute kg/luna]] -> 764 | R3: =Таблица3[[#This Row],[Vandute kg/luna]]*(Таблица3[[#This Row],[Pret receptie unitar/RON]]+((Таблица3[[#This Row],[Pret receptie unitar/RON]]*25)/100)) -> 14000 | S3: =Таблица3[[#This Row],[Vandute/RON]]-Таблица3[[#This Row],[Cheltuieli]] -> -146000
A4: =A3+1 -> 3 | B4: Vitamin C | C4: Medicamente | D4: buc/ml | E4: 44074 | F4: 44075 | G4: D - B | H4: =IF(Таблица3[[#This Row],[Denumire grup]]=Ghid!$B$6,"A1 - A10",IF(Таблица3[[#This Row],[Denumire grup]]=Ghid!$B$5,"A11 - A20",IF(Таблица3[[#This Row],[Denumire grup]]=Ghid!$B$7,"B1 - B5",IF(Таблица3[[#This Row],[Denumire grup]]=Ghid!$B$8,"B6 - B15",IF(Таблица3[[#This Row],[Denumire grup]]=Ghid!$B$9,"B16 - B30",IF(Таблица3[[#This Row],[Denumire grup]]=Ghid!$B$10,"C1 - C20","C21 - C30")))))) -> B1 - B5 | I4: 1500 | J4: =IF(Таблица3[[#This Row],[Data livrare]]>Таблица3[[#This Row],[Data de receptionate]],Ghid!$D$15,Ghid!$D$16) -> Livrat | K4: Timisoare | L4: 300 | M4: =Таблица3[[#This Row],[Pret receptie unitar/RON]]*Таблица3[[#This Row],[Cantitate de produs]] -> 450000 | N4: Curier | O4: =Таблица3[[#This Row],[Cantitate de produs]]+20 -> 1520 | P4: 10 | Q4: =Таблица3[[#This Row],[Cantitate Total kg]]-Таблица3[[#This Row],[Vandute kg/luna]] -> 1510 | R4: =Таблица3[[#This Row],[Vandute kg/luna]]*(Таблица3[[#This Row],[Pret receptie unitar/RON]]+((Таблица3[[#This Row],[Pret receptie unitar/RON]]*25)/100)) -> 3750 | S4: =Таблица3[[#This Row],[Vandute/RON]]-Таблица3[[#This Row],[Cheltuieli]] -> -446250
A5: =A4+1 -> 4 | B5: Vitamin D | C5: Medicamente | D5: buc/ml | E5: 44068 | G5: D - B | H5: =IF(Таблица3[[#This Row],[Denumire grup]]=Ghid!$B$6,"A1 - A10",IF(Таблица3[[#This Row],[Denumire grup]]=Ghid!$B$5,"A11 - A20",IF(Таблица3[[#This Row],[Denumire grup]]=Ghid!$B$7,"B1 - B5",IF(Таблица3[[#This Row],[Denumire grup]]=Ghid!$B$8,"B6 - B15",IF(Таблица3[[#This Row],[Denumire grup]]=Ghid!$B$9,"B16 - B30",IF(Таблица3[[#This Row],[Denumire grup]]=Ghid!$B$10,"C1 - C20","C21 - C30")))))) -> B1 - B5 | I5: 600 | J5: =IF(Таблица3[[#This Row],[Data livrare]]>Таблица3[[#This Row],[Data de receptionate]],Ghid!$D$15,Ghid!$D$16) -> Nelivrat | K5: Brasov | L5: 45 | M5: =Таблица3[[#This Row],[Pret receptie unitar/RON]]*Таблица3[[#This Row],[Cantitate de produs]] -> 27000 | N5: Transport partener | O5: =Таблица3[[#This Row],[Cantitate de produs]]+20 -> 620 | P5: 45 | Q5: =Таблица3[[#This Row],[Cantitate Total kg]]-Таблица3[[#This Row],[Vandute kg/luna]] -> 575 | R5: =Таблица3[[#This Row],[Vandute kg/luna]]*(Таблица3[[#This Row],[Pret receptie unitar/RON]]+((Таблица3[[#This Row],[Pret receptie unitar/RON]]*25)/100)) -> 2531.25 | S5: =Таблица3[[#This Row],[Vandute/RON]]-Таблица3[[#This Row],[Cheltuieli]] -> -24468.75
A6: =A5+1 -> 5 | B6: Vit C lichid | C6: Medicamente | D6: buc/ml | E6: 44154 | F6: 44155 | G6: D - B | H6: =IF(Таблица3[[#This Row],[Denumire grup]]=Ghid!$B$6,"A1 - A10",IF(Таблица3[[#This Row],[Denumire grup]]=Ghid!$B$5,"A11 - A20",IF(Таблица3[[#This Row],[Denumire grup]]=Ghid!$B$7,"B1 - B5",IF(Таблица3[[#This Row],[Denumire grup]]=Ghid!$B$8,"B6 - B15",IF(Таблица3[[#This Row],[Denumire grup]]=Ghid!$B$9,"B16 - B30",IF(Таблица3[[#This Row],[Denumire grup]]=Ghid!$B$10,"C1 - C20","C21 - C30")))))) -> B1 - B5 | I6: 300 | J6: =IF(Таблица3[[#This Row],[Data livrare]]>Таблица3[[#This Row],[Data de receptionate]],Ghid!$D$15,Ghid!$D$16) -> Livrat | K6: Timisoare | L6: 78 | M6: =Таблица3[[#This Row],[Pret receptie unitar/RON]]*Таблица3[[#This Row],[Cantitate de produs]] -> 23400 | N6: Transport firma | O6: =Таблица3[[#This Row],[Cantitate de produs]]+20 -> 320 | P6: 12 | Q6: =Таблица3[[#This Row],[Cantitate Total kg]]-Таблица3[[#This Row],[Vandute kg/luna]] -> 308 | R6: =Таблица3[[#This Row],[Vandute kg/luna]]*(Таблица3[[#This Row],[Pret receptie unitar/RON]]+((Таблица3[[#This Row],[Pret receptie unitar/RON]]*25)/100)) -> 1170 | S6: =Таблица3[[#This Row],[Vandute/RON]]-Таблица3[[#This Row],[Cheltuieli]] -> -22230
A7: =A6+1 -> 6 | B7: Vopsea Rosu | C7: Bauturi | D7: buc/l | E7: 44428 | F7: 44429 | G7: D - C | H7: =IF(Таблица3[[#This Row],[Denumire grup]]=Ghid!$B$6,"A1 - A10",IF(Таблица3[[#This Row],[Denumire grup]]=Ghid!$B$5,"A11 - A20",IF(Таблица3[[#This Row],[Denumire grup]]=Ghid!$B$7,"B1 - B5",IF(Таблица3[[#This Row],[Denumire grup]]=Ghid!$B$8,"B6 - B15",IF(Таблица3[[#This Row],[Denumire grup]]=Ghid!$B$9,"B16 - B30",IF(Таблица3[[#This Row],[Denumire grup]]=Ghid!$B$10,"C1 - C20","C21 - C30")))))) -> C1 - C20 | I7: 4562 | J7: =IF(Таблица3[[#This Row],[Data livrare]]>Таблица3[[#This Row],[Data de receptionate]],Ghid!$D$15,Ghid!$D$16) -> Livrat | K7: Alba - Iulia | L7: 96 | M7: =Таблица3[[#This Row],[Pret receptie unitar/RON]]*Таблица3[[#This Row],[Cantitate de produs]] -> 437952 | N7: Transport partener | O7: =Таблица3[[#This Row],[Cantitate de produs]]+20 -> 4582 | P7: 100 | Q7: =Таблица3[[#This Row],[Cantitate Total kg]]-Таблица3[[#This Row],[Vandute kg/luna]] -> 4482 | R7: =Таблица3[[#This Row],[Vandute kg/luna]]*(Таблица3[[#This Row],[Pret receptie unitar/RON]]+((Таблица3[[#This Row],[Pret receptie unitar/RON]]*25)/100)) -> 12000 | S7: =Таблица3[[#This Row],[Vandute/RON]]-Таблица3[[#This Row],[Cheltuieli]] -> -425952
A8: =A7+1 -> 7 | B8: Traversa 80 | C8: Materiale constructie | D8: mm | E8: 44455 | G8: D - A | H8: =IF(Таблица3[[#This Row],[Denumire grup]]=Ghid!$B$6,"A1 - A10",IF(Таблица3[[#This Row],[Denumire grup]]=Ghid!$B$5,"A11 - A20",IF(Таблица3[[#This Row],[Denumire grup]]=Ghid!$B$7,"B1 - B5",IF(Таблица3[[#This Row],[Denumire grup]]=Ghid!$B$8,"B6 - B15",IF(Таблица3[[#This Row],[Denumire grup]]=Ghid!$B$9,"B16 - B30",IF(Таблица3[[#This Row],[Denumire grup]]=Ghid!$B$10,"C1 - C20","C21 - C30")))))) -> A11 - A20 | I8: 5600 | J8: =IF(Таблица3[[#This Row],[Data livrare]]>Таблица3[[#This Row],[Data de receptionate]],Ghid!$D$15,Ghid!$D$16) -> Nelivrat | K8: Constanta | L8: 45 | M8: =Таблица3[[#This Row],[Pret receptie unitar/RON]]*Таблица3[[#This Row],[Cantitate de produs]] -> 252000 | N8: Personal fizic | O8: =Таблица3[[#This Row],[Cantitate de produs]]+20 -> 5620 | P8: 656 | Q8: =Таблица3[[#This Row],[Cantitate Total kg]]-Таблица3[[#This Row],[Vandute kg/luna]] -> 4964 | R8: =Таблица3[[#This Row],[Vandute kg/luna]]*(Таблица3[[#This Row],[Pret receptie unitar/RON]]+((Таблица3[[#This Row],[Pret receptie unitar/RON]]*25)/100)) -> 36900 | S8: =Таблица3[[#This Row],[Vandute/RON]]-Таблица3[[#This Row],[Cheltuieli]] -> -215100
A9: =A8+1 -> 8 | B9: Pungi | C9: Materiale constructie | D9: pachet | E9: 44150 | G9: D - A | H9: =IF(Таблица3[[#This Row],[Denumire grup]]=Ghid!$B$6,"A1 - A10",IF(Таблица3[[#This Row],[Denumire grup]]=Ghid!$B$5,"A11 - A20",IF(Таблица3[[#This Row],[Denumire grup]]=Ghid!$B$7,"B1 - B5",IF(Таблица3[[#This Row],[Denumire grup]]=Ghid!$B$8,"B6 - B15",IF(Таблица3[[#This Row],[Denumire grup]]=Ghid!$B$9,"B16 - B30",IF(Таблица3[[#This Row],[Denumire grup]]=Ghid!$B$10,"C1 - C20","C21 - C30")))))) -> A11 - A20 | I9: 1235 | J9: =IF(Таблица3[[#This Row],[Data livrare]]>Таблица3[[#This Row],[Data de receptionate]],Ghid!$D$15,Ghid!$D$16) -> Nelivrat | K9: Craiova | L9: 250 | M9: =Таблица3[[#This Row],[Pret receptie unitar/RON]]*Таблица3[[#This Row],[Cantitate de produs]] -> 308750 | N9: Personal fizic | O9: =Таблица3[[#This Row],[Cantitate de produs]]+20 -> 1255 | P9: 453 | Q9: =Таблица3[[#This Row],[Cantitate Total kg]]-Таблица3[[#This Row],[Vandute kg/luna]] -> 802 | R9: =Таблица3[[#This Row],[Vandute kg/luna]]*(Таблица3[[#This Row],[Pret receptie unitar/RON]]+((Таблица3[[#This Row],[Pret receptie unitar/RON]]*25)/100)) -> 141562.5 | S9: =Таблица3[[#This Row],[Vandute/RON]]-Таблица3[[#This Row],[Cheltuieli]] -> -167187.5
A10: =A9+1 -> 9 | B10: Bere negru | C10: Materiale constructie | D10: buc | E10: 44344 | F10: 44376 | G10: D - A | H10: =IF(Таблица3[[#This Row],[Denumire grup]]=Ghid!$B$6,"A1 - A10",IF(Таблица3[[#This Row],[Denumire grup]]=Ghid!$B$5,"A11 - A20",IF(Таблица3[[#This Row],[Denumire grup]]=Ghid!$B$7,"B1 - B5",IF(Таблица3[[#This Row],[Denumire grup]]=Ghid!$B$8,"B6 - B15",IF(Таблица3[[#This Row],[Denumire grup]]=Ghid!$B$9,"B16 - B30",IF(Таблица3[[#This Row],[Denumire grup]]=Ghid!$B$10,"C1 - C20","C21 - C30")))))) -> A11 - A20 | I10: 4569 | J10: Retur | K10: Bucuresti | L10: 300 | M10: =Таблица3[[#This Row],[Pret receptie unitar/RON]]*Таблица3[[#This Row],[Cantitate de produs]] -> 1370700 | N10: Curier | O10: =Таблица3[[#This Row],[Cantitate de produs]]+20 -> 4589 | P10: 12 | Q10: =Таблица3[[#This Row],[Cantitate Total kg]]-Таблица3[[#This Row],[Vandute kg/luna]] -> 4577 | R10: =Таблица3[[#This Row],[Vandute kg/luna]]*(Таблица3[[#This Row],[Pret receptie unitar/RON]]+((Таблица3[[#This Row],[Pret receptie unitar/RON]]*25)/100)) -> 4500 | S10: =Таблица3[[#This Row],[Vandute/RON]]-Таблица3[[#This Row],[Cheltuieli]] -> -1366200
A11: =A10+1 -> 10 | B11: Varza | C11: Alimente | D11: buc/kg | E11: 44076 | F11: 44109 | G11: D - A | H11: =IF(Таблица3[[#This Row],[Denumire grup]]=Ghid!$B$6,"A1 - A10",IF(Таблица3[[#This Row],[Denumire grup]]=Ghid!$B$5,"A11 - A20",IF(Таблица3[[#This Row],[Denumire grup]]=Ghid!$B$7,"B1 - B5",IF(Таблица3[[#This Row],[Denumire grup]]=Ghid!$B$8,"B6 - B15",IF(Таблица3[[#This Row],[Denumire grup]]=Ghid!$B$9,"B16 - B30",IF(Таблица3[[#This Row],[Denumire grup]]=Ghid!$B$10,"C1 - C20","C21 - C30")))))) -> A1 - A10 | I11: 456 | J11: =IF(Таблица3[[#This Row],[Data livrare]]>Таблица3[[#This Row],[Data de receptionate]],Ghid!$D$15,Ghid!$D$16) -> Livrat | K11: Bucuresti | L11: 456 | M11: =Таблица3[[#This Row],[Pret receptie unitar/RON]]*Таблица3[[#This Row],[Cantitate de produs]] -> 207936 | N11: Transport firma | O11: =Таблица3[[#This Row],[Cantitate de produs]]+20 -> 476 | P11: 48 | Q11: =Таблица3[[#This Row],[Cantitate Total kg]]-Таблица3[[#This Row],[Vandute kg/luna]] -> 428 | R11: =Таблица3[[#This Row],[Vandute kg/luna]]*(Таблица3[[#This Row],[Pret receptie unitar/RON]]+((Таблица3[[#This Row],[Pret receptie unitar/RON]]*25)/100)) -> 27360 | S11: =Таблица3[[#This Row],[Vandute/RON]]-Таблица3[[#This Row],[Cheltuieli]] -> -180576
A12: =A11+1 -> 11 | B12: Rosie | C12: Alimente | D12: buc/kg | E12: 43906 | F12: 43908 | G12: D - A | H12: =IF(Таблица3[[#This Row],[Denumire grup]]=Ghid!$B$6,"A1 - A10",IF(Таблица3[[#This Row],[Denumire grup]]=Ghid!$B$5,"A11 - A20",IF(Таблица3[[#This Row],[Denumire grup]]=Ghid!$B$7,"B1 - B5",IF(Таблица3[[#This Row],[Denumire grup]]=Ghid!$B$8,"B6 - B15",IF(Таблица3[[#This Row],[Denumire grup]]=Ghid!$B$9,"B16 - B30",IF(Таблица3[[#This Row],[Denumire grup]]=Ghid!$B$10,"C1 - C20","C21 - C30")))))) -> A1 - A10 | I12: 1254 | J12: =IF(Таблица3[[#This Row],[Data livrare]]>Таблица3[[#This Row],[Data de receptionate]],Ghid!$D$15,Ghid!$D$16) -> Livrat | K12: Cluj - Napoca | L12: 125 | M12: =Таблица3[[#This Row],[Pret receptie unitar/RON]]*Таблица3[[#This Row],[Cantitate de produs]] -> 156750 | N12: Personal fizic | O12: =Таблица3[[#This Row],[Cantitate de produs]]+20 -> 1274 | P12: 99 | Q12: =Таблица3[[#This Row],[Cantitate Total kg]]-Таблица3[[#This Row],[Vandute kg/luna]] -> 1175 | R12: =Таблица3[[#This Row],[Vandute kg/luna]]*(Таблица3[[#This Row],[Pret receptie unitar/RON]]+((Таблица3[[#This Row],[Pret receptie unitar/RON]]*25)/100)) -> 15468.75 | S12: =Таблица3[[#This Row],[Vandute/RON]]-Таблица3[[#This Row],[Cheltuieli]] -> -141281.25
A13: =A12+1 -> 12 | B13: Vitamin C | C13: Medicamente | D13: buc/ml | E13: 43907 | F13: 43909 | G13: D - B | H13: =IF(Таблица3[[#This Row],[Denumire grup]]=Ghid!$B$6,"A1 - A10",IF(Таблица3[[#This Row],[Denumire grup]]=Ghid!$B$5,"A11 - A20",IF(Таблица3[[#This Row],[Denumire grup]]=Ghid!$B$7,"B1 - B5",IF(Таблица3[[#This Row],[Denumire grup]]=Ghid!$B$8,"B6 - B15",IF(Таблица3[[#This Row],[Denumire grup]]=Ghid!$B$9,"B16 - B30",IF(Таблица3[[#This Row],[Denumire grup]]=Ghid!$B$10,"C1 - C20","C21 - C30")))))) -> B1 - B5 | I13: 6365 | J13: =IF(Таблица3[[#This Row],[Data livrare]]>Таблица3[[#This Row],[Data de receptionate]],Ghid!$D$15,Ghid!$D$16) -> Livrat | K13: Timisoare | L13: 46 | M13: =Таблица3[[#This Row],[Pret receptie unitar/RON]]*Таблица3[[#This Row],[Cantitate de produs]] -> 292790 | N13: Curier | O13: =Таблица3[[#This Row],[Cantitate de produs]]+20 -> 6385 | P13: 50 | Q13: =Таблица3[[#This Row],[Cantitate Total kg]]-Таблица3[[#This Row],[Vandute kg/luna]] -> 6335 | R13: =Таблица3[[#This Row],[Vandute kg/luna]]*(Таблица3[[#This Row],[Pret receptie unitar/RON]]+((Таблица3[[#This Row],[Pret receptie unitar/RON]]*25)/100)) -> 2875 | S13: =Таблица3[[#This Row],[Vandute/RON]]-Таблица3[[#This Row],[Cheltuieli]] -> -289915
A14: =A13+1 -> 13 | B14: Vitamin D | C14: Medicamente | D14: buc/ml | E14: 43907 | F14: 43939 | G14: D - B | H14: =IF(Таблица3[[#This Row],[Denumire grup]]=Ghid!$B$6,"A1 - A10",IF(Таблица3[[#This Row],[Denumire grup]]=Ghid!$B$5,"A11 - A20",IF(Таблица3[[#This Row],[Denumire grup]]=Ghid!$B$7,"B1 - B5",IF(Таблица3[[#This Row],[Denumire grup]]=Ghid!$B$8,"B6 - B15",IF(Таблица3[[#This Row],[Denumire grup]]=Ghid!$B$9,"B16 - B30",IF(Таблица3[[#This Row],[Denumire grup]]=Ghid!$B$10,"C1 - C20","C21 - C30")))))) -> B1 - B5 | I14: 4563 | J14: =IF(Таблица3[[#This Row],[Data livrare]]>Таблица3[[#This Row],[Data de receptionate]],Ghid!$D$15,Ghid!$D$16) -> Livrat | K14: Brasov | L14: 80 | M14: =Таблица3[[#This Row],[Pret receptie unitar/RON]]*Таблица3[[#This Row],[Cantitate de produs]] -> 365040 | N14: Transport partener | O14: =Таблица3[[#This Row],[Cantitate de produs]]+20 -> 4583 | P14: 12 | Q14: =Таблица3[[#This Row],[Cantitate Total kg]]-Таблица3[[#This Row],[Vandute kg/luna]] -> 4571 | R14: =Таблица3[[#This Row],[Vandute kg/luna]]*(Таблица3[[#This Row],[Pret receptie unitar/RON]]+((Таблица3[[#This Row],[Pret receptie unitar/RON]]*25)/100)) -> 1200 | S14: =Таблица3[[#This Row],[Vandute/RON]]-Таблица3[[#This Row],[Cheltuieli]] -> -363840
A15: =A14+1 -> 14 | B15: Vit C lichid | C15: Medicamente | D15: buc/ml | E15: 43969 | G15: D - B | H15: =IF(Таблица3[[#This Row],[Denumire grup]]=Ghid!$B$6,"A1 - A10",IF(Таблица3[[#This Row],[Denumire grup]]=Ghid!$B$5,"A11 - A20",IF(Таблица3[[#This Row],[Denumire grup]]=Ghid!$B$7,"B1 - B5",IF(Таблица3[[#This Row],[Denumire grup]]=Ghid!$B$8,"B6 - B15",IF(Таблица3[[#This Row],[Denumire grup]]=Ghid!$B$9,"B16 - B30",IF(Таблица3[[#This Row],[Denumire grup]]=Ghid!$B$10,"C1 - C20","C21 - C30")))))) -> B1 - B5 | I15: 1235 | J15: =IF(Таблица3[[#This Row],[Data livrare]]>Таблица3[[#This Row],[Data de receptionate]],Ghid!$D$15,Ghid!$D$16) -> Nelivrat | K15: Timisoare | L15: 90 | M15: =Таблица3[[#This Row],[Pret receptie unitar/RON]]*Таблица3[[#This Row],[Cantitate de produs]] -> 111150 | N15: Transport firma | O15: =Таблица3[[#This Row],[Cantitate de produs]]+20 -> 1255 | P15: 1250 | Q15: =Таблица3[[#This Row],[Cantitate Total kg]]-Таблица3[[#This Row],[Vandute kg/luna]] -> 5 | R15: =Таблица3[[#This Row],[Vandute kg/luna]]*(Таблица3[[#This Row],[Pret receptie unitar/RON]]+((Таблица3[[#This Row],[Pret receptie unitar/RON]]*25)/100)) -> 140625 | S15: =Таблица3[[#This Row],[Vandute/RON]]-Таблица3[[#This Row],[Cheltuieli]] -> 29475
A16: =A15+1 -> 15 | B16: Vopsea Rosu | C16: Vopsea | D16: buc/l | E16: 44103 | G16: D - B | H16: =IF(Таблица3[[#This Row],[Denumire grup]]=Ghid!$B$6,"A1 - A10",IF(Таблица3[[#This Row],[Denumire grup]]=Ghid!$B$5,"A11 - A20",IF(Таблица3[[#This Row],[Denumire grup]]=Ghid!$B$7,"B1 - B5",IF(Таблица3[[#This Row],[Denumire grup]]=Ghid!$B$8,"B6 - B15",IF(Таблица3[[#This Row],[Denumire grup]]=Ghid!$B$9,"B16 - B30",IF(Таблица3[[#This Row],[Denumire grup]]=Ghid!$B$10,"C1 - C20","C21 - C30")))))) -> B6 - B15 | I16: 7896 | J16: In asteptare | K16: Alba - Iulia | L16: 55 | M16: =Таблица3[[#This Row],[Pret receptie unitar/RON]]*Таблица3[[#This Row],[Cantitate de produs]] -> 434280 | N16: Transport partener | O16: =Таблица3[[#This Row],[Cantitate de produs]]+20 -> 7916 | P16: 400 | Q16: =Таблица3[[#This Row],[Cantitate Total kg]]-Таблица3[[#This Row],[Vandute kg/luna]] -> 7516 | R16: =Таблица3[[#This Row],[Vandute kg/luna]]*(Таблица3[[#This Row],[Pret receptie unitar/RON]]+((Таблица3[[#This Row],[Pret receptie unitar/RON]]*25)/100)) -> 27500 | S16: =Таблица3[[#This Row],[Vandute/RON]]-Таблица3[[#This Row],[Cheltuieli]] -> -406780
A17: =A16+1 -> 16 | B17: Traversa 81 | C17: Materiale constructie | D17: mm | E17: 43969 | F17: 43976 | G17: D - A | H17: =IF(Таблица3[[#This Row],[Denumire grup]]=Ghid!$B$6,"A1 - A10",IF(Таблица3[[#This Row],[Denumire grup]]=Ghid!$B$5,"A11 - A20",IF(Таблица3[[#This Row],[Denumire grup]]=Ghid!$B$7,"B1 - B5",IF(Таблица3[[#This Row],[Denumire grup]]=Ghid!$B$8,"B6 - B15",IF(Таблица3[[#This Row],[Denumire grup]]=Ghid!$B$9,"B16 - B30",IF(Таблица3[[#This Row],[Denumire grup]]=Ghid!$B$10,"C1 - C20","C21 - C30")))))) -> A11 - A20 | I17: 5645 | J17: =IF(Таблица3[[#This Row],[Data livrare]]>Таблица3[[#This Row],[Data de receptionate]],Ghid!$D$15,Ghid!$D$16) -> Livrat | K17: Constanta | L17: 63 | M17: =Таблица3[[#This Row],[Pret receptie unitar/RON]]*Таблица3[[#This Row],[Cantitate de produs]] -> 355635 | N17: Personal fizic | O17: =Таблица3[[#This Row],[Cantitate de produs]]+20 -> 5665 | P17: 152 | Q17: =Таблица3[[#This Row],[Cantitate Total kg]]-Таблица3[[#This Row],[Vandute kg/luna]] -> 5513 | R17: =Таблица3[[#This Row],[Vandute kg/luna]]*(Таблица3[[#This Row],[Pret receptie unitar/RON]]+((Таблица3[[#This Row],[Pret receptie unitar/RON]]*25)/100)) -> 11970 | S17: =Таблица3[[#This Row],[Vandute/RON]]-Таблица3[[#This Row],[Cheltuieli]] -> -343665
A18: =A17+1 -> 17 | B18: Masina de spalat | C18: Electrocasnice si Climitizare | D18: buc | E18: 43969 | F18: 44001 | G18: D - B | H18: =IF(Таблица3[[#This Row],[Denumire grup]]=Ghid!$B$6,"A1 - A10",IF(Таблица3[[#This Row],[Denumire grup]]=Ghid!$B$5,"A11 - A20",IF(Таблица3[[#This Row],[Denumire grup]]=Ghid!$B$7,"B1 - B5",IF(Таблица3[[#This Row],[Denumire grup]]=Ghid!$B$8,"B6 - B15",IF(Таблица3[[#This Row],[Denumire grup]]=Ghid!$B$9,"B16 - B30",IF(Таблица3[[#This Row],[Denumire grup]]=Ghid!$B$10,"C1 - C20","C21 - C30")))))) -> B16 - B30 | I18: 4563 | J18: =IF(Таблица3[[#This Row],[Data livrare]]>Таблица3[[#This Row],[Data de receptionate]],Ghid!$D$15,Ghid!$D$16) -> Livrat | K18: Timisoare | L18: 125 | M18: =Таблица3[[#This Row],[Pret receptie unitar/RON]]*Таблица3[[#This Row],[Cantitate de produs]] -> 570375 | N18: Curier | O18: =Таблица3[[#This Row],[Cantitate de produs]]+20 -> 4583 | P18: 656 | Q18: =Таблица3[[#This Row],[Cantitate Total kg]]-Таблица3[[#This Row],[Vandute kg/luna]] -> 3927 | R18: =Таблица3[[#This Row],[Vandute kg/luna]]*(Таблица3[[#This Row],[Pret receptie unitar/RON]]+((Таблица3[[#This Row],[Pret receptie unitar/RON]]*25)/100)) -> 102500 | S18: =Таблица3[[#This Row],[Vandute/RON]]-Таблица3[[#This Row],[Cheltuieli]] -> -467875
A19: =A18+1 -> 18 | B19: Cana filtrate | C19: Electrocasnice si Climitizare | D19: buc | E19: 44103 | F19: 44134 | G19: D - B | H19: =IF(Таблица3[[#This Row],[Denumire grup]]=Ghid!$B$6,"A1 - A10",IF(Таблица3[[#This Row],[Denumire grup]]=Ghid!$B$5,"A11 - A20",IF(Таблица3[[#This Row],[Denumire grup]]=Ghid!$B$7,"B1 - B5",IF(Таблица3[[#This Row],[Denumire grup]]=Ghid!$B$8,"B6 - B15",IF(Таблица3[[#This Row],[Denumire grup]]=Ghid!$B$9,"B16 - B30",IF(Таблица3[[#This Row],[Denumire grup]]=Ghid!$B$10,"C1 - C20","C21 - C30")))))) -> B16 - B30 | I19: 1235 | J19: =IF(Таблица3[[#This Row],[Data livrare]]>Таблица3[[#This Row],[Data de receptionate]],Ghid!$D$15,Ghid!$D$16) -> Livrat | K19: Alba - Iulia | L19: 46 | M19: =Таблица3[[#This Row],[Pret receptie unitar/RON]]*Таблица3[[#This Row],[Cantitate de produs]] -> 56810 | N19: Transport firma | O19: =Таблица3[[#This Row],[Cantitate de produs]]+20 -> 1255 | P19: 453 | Q19: =Таблица3[[#This Row],[Cantitate Total kg]]-Таблица3[[#This Row],[Vandute kg/luna]] -> 802 | R19: =Таблица3[[#This Row],[Vandute kg/luna]]*(Таблица3[[#This Row],[Pret receptie unitar/RON]]+((Таблица3[[#This Row],[Pret receptie unitar/RON]]*25)/100)) -> 26047.5 | S19: =Таблица3[[#This Row],[Vandute/RON]]-Таблица3[[#This Row],[Cheltuieli]] -> -30762.5
A20: =A19+1 -> 19 | B20: Masina electrica | C20: Electrocasnice si Climitizare | D20: buc | E20: 44344 | F20: 44345 | G20: D - B | H20: =IF(Таблица3[[#This Row],[Denumire grup]]=Ghid!$B$6,"A1 - A10",IF(Таблица3[[#This Row],[Denumire grup]]=Ghid!$B$5,"A11 - A20",IF(Таблица3[[#This Row],[Denumire grup]]=Ghid!$B$7,"B1 - B5",IF(Таблица3[[#This Row],[Denumire grup]]=Ghid!$B$8,"B6 - B15",IF(Таблица3[[#This Row],[Denumire grup]]=Ghid!$B$9,"B16 - B30",IF(Таблица3[[#This Row],[Denumire grup]]=Ghid!$B$10,"C1 - C20","C21 - C30")))))) -> B16 - B30 | I20: 7896 | J20: =IF(Таблица3[[#This Row],[Data livrare]]>Таблица3[[#This Row],[Data de receptionate]],Ghid!$D$15,Ghid!$D$16) -> Livrat | K20: Constanta | L20: 80 | M20: =Таблица3[[#This Row],[Pret receptie unitar/RON]]*Таблица3[[#This Row],[Cantitate de produs]] -> 631680 | N20: Personal fizic | O20: =Таблица3[[#This Row],[Cantitate de produs]]+20 -> 7916 | P20: 12 | Q20: =Таблица3[[#This Row],[Cantitate Total kg]]-Таблица3[[#This Row],[Vandute kg/luna]] -> 7904 | R20: =Таблица3[[#This Row],[Vandute kg/luna]]*(Таблица3[[#This Row],[Pret receptie unitar/RON]]+((Таблица3[[#This Row],[Pret receptie unitar/RON]]*25)/100)) -> 1200 | S20: =Таблица3[[#This Row],[Vandute/RON]]-Таблица3[[#This Row],[Cheltuieli]] -> -630480
A21: =A20+1 -> 20 | B21: Bere Carlsberg | C21: Bauturi | D21: buc | E21: 44076 | F21: 44089 | G21: D - C | H21: =IF(Таблица3[[#This Row],[Denumire grup]]=Ghid!$B$6,"A1 - A10",IF(Таблица3[[#This Row],[Denumire grup]]=Ghid!$B$5,"A11 - A20",IF(Таблица3[[#This Row],[Denumire grup]]=Ghid!$B$7,"B1 - B5",IF(Таблица3[[#This Row],[Denumire grup]]=Ghid!$B$8,"B6 - B15",IF(Таблица3[[#This Row],[Denumire grup]]=Ghid!$B$9,"B16 - B30",IF(Таблица3[[#This Row],[Denumire grup]]=Ghid!$B$10,"C1 - C20","C21 - C30")))))) -> C1 - C20 | I21: 5645 | J21: =IF(Таблица3[[#This Row],[Data livrare]]>Таблица3[[#This Row],[Data de receptionate]],Ghid!$D$15,Ghid!$D$16) -> Livrat | K21: Craiova | L21: 90 | M21: =Таблица3[[#This Row],[Pret receptie unitar/RON]]*Таблица3[[#This Row],[Cantitate de produs]] -> 508050 | N21: Curier | O21: =Таблица3[[#This Row],[Cantitate de produs]]+20 -> 5665 | P21: 48 | Q21: =Таблица3[[#This Row],[Cantitate Total kg]]-Таблица3[[#This Row],[Vandute kg/luna]] -> 5617 | R21: =Таблица3[[#This Row],[Vandute kg/luna]]*(Таблица3[[#This Row],[Pret receptie unitar/RON]]+((Таблица3[[#This Row],[Pret receptie unitar/RON]]*25)/100)) -> 5400 | S21: =Таблица3[[#This Row],[Vandute/RON]]-Таблица3[[#This Row],[Cheltuieli]] -> -502650
A22: =A21+1 -> 21 | B22: Bere Neumarc | C22: Bauturi | D22: buc | E22: 43906 | F22: 43939 | G22: D - C | H22: =IF(Таблица3[[#This Row],[Denumire grup]]=Ghid!$B$6,"A1 - A10",IF(Таблица3[[#This Row],[Denumire grup]]=Ghid!$B$5,"A11 - A20",IF(Таблица3[[#This Row],[Denumire grup]]=Ghid!$B$7,"B1 - B5",IF(Таблица3[[#This Row],[Denumire grup]]=Ghid!$B$8,"B6 - B15",IF(Таблица3[[#This Row],[Denumire grup]]=Ghid!$B$9,"B16 - B30",IF(Таблица3[[#This Row],[Denumire grup]]=Ghid!$B$10,"C1 - C20","C21 - C30")))))) -> C1 - C20 | I22: 5600 | J22: =IF(Таблица3[[#This Row],[Data livrare]]>Таблица3[[#This Row],[Data de receptionate]],Ghid!$D$15,Ghid!$D$16) -> Livrat | K22: Bucuresti | L22: 55 | M22: =Таблица3[[#This Row],[Pret receptie unitar/RON]]*Таблица3[[#This Row],[Cantitate de produs]] -> 308000 | N22: Transport partener | O22: =Таблица3[[#This Row],[Cantitate de produs]]+20 -> 5620 | P22: 99 | Q22: =Таблица3[[#This Row],[Cantitate Total kg]]-Таблица3[[#This Row],[Vandute kg/luna]] -> 5521 | R22: =Таблица3[[#This Row],[Vandute kg/luna]]*(Таблица3[[#This Row],[Pret receptie unitar/RON]]+((Таблица3[[#This Row],[Pret receptie unitar/RON]]*25)/100)) -> 6806.25 | S22: =Таблица3[[#This Row],[Vandute/RON]]-Таблица3[[#This Row],[Cheltuieli]] -> -301193.75
A23: =A22+1 -> 22 | B23: Cosuri 5l | C23: Materiale constructie | D23: buc | E23: 43907 | F23: 43941 | G23: D - A | H23: =IF(Таблица3[[#This Row],[Denumire grup]]=Ghid!$B$6,"A1 - A10",IF(Таблица3[[#This Row],[Denumire grup]]=Ghid!$B$5,"A11 - A20",IF(Таблица3[[#This Row],[Denumire grup]]=Ghid!$B$7,"B1 - B5",IF(Таблица3[[#This Row],[Denumire grup]]=Ghid!$B$8,"B6 - B15",IF(Таблица3[[#This Row],[Denumire grup]]=Ghid!$B$9,"B16 - B30",IF(Таблица3[[#This Row],[Denumire grup]]=Ghid!$B$10,"C1 - C20","C21 - C30")))))) -> A11 - A20 | I23: 1235 | J23: Retur | K23: Cluj - Napoca | L23: 200 | M23: =Таблица3[[#This Row],[Pret receptie unitar/RON]]*Таблица3[[#This Row],[Cantitate de produs]] -> 247000 | N23: Transport firma | O23: =Таблица3[[#This Row],[Cantitate de produs]]+20 -> 1255 | P23: 50 | Q23: =Таблица3[[#This Row],[Cantitate Total kg]]-Таблица3[[#This Row],[Vandute kg/luna]] -> 1205 | R23: =Таблица3[[#This Row],[Vandute kg/luna]]*(Таблица3[[#This Row],[Pret receptie unitar/RON]]+((Таблица3[[#This Row],[Pret receptie unitar/RON]]*25)/100)) -> 12500 | S23: =Таблица3[[#This Row],[Vandute/RON]]-Таблица3[[#This Row],[Cheltuieli]] -> -234500
A24: =A23+1 -> 23 | B24: Detergent 2l | C24: Materiale constructie | D24: buc | E24: 43907 | F24: 43939 | G24: D - A | H24: =IF(Таблица3[[#This Row],[Denumire grup]]=Ghid!$B$6,"A1 - A10",IF(Таблица3[[#This Row],[Denumire grup]]=Ghid!$B$5,"A11 - A20",IF(Таблица3[[#This Row],[Denumire grup]]=Ghid!$B$7,"B1 - B5",IF(Таблица3[[#This Row],[Denumire grup]]=Ghid!$B$8,"B6 - B15",IF(Таблица3[[#This Row],[Denumire grup]]=Ghid!$B$9,"B16 - B30",IF(Таблица3[[#This Row],[Denumire grup]]=Ghid!$B$10,"C1 - C20","C21 - C30")))))) -> A11 - A20 | I24: 4569 | J24: =IF(Таблица3[[#This Row],[Data livrare]]>Таблица3[[#This Row],[Data de receptionate]],Ghid!$D$15,Ghid!$D$16) -> Livrat | K24: Timisoare | L24: 300 | M24: =Таблица3[[#This Row],[Pret receptie unitar/RON]]*Таблица3[[#This Row],[Cantitate de produs]] -> 1370700 | N24: Transport partener | O24: =Таблица3[[#This Row],[Cantitate de produs]]+20 -> 4589 | P24: 56 | Q24: =Таблица3[[#This Row],[Cantitate Total kg]]-Таблица3[[#This Row],[Vandute kg/luna]] -> 4533 | R24: =Таблица3[[#This Row],[Vandute kg/luna]]*(Таблица3[[#This Row],[Pret receptie unitar/RON]]+((Таблица3[[#This Row],[Pret receptie unitar/RON]]*25)/100)) -> 21000 | S24: =Таблица3[[#This Row],[Vandute/RON]]-Таблица3[[#This Row],[Cheltuieli]] -> -1349700
A25: =A24+1 -> 24 | B25: Detergent 5l | C25: Materiale constructie | D25: buc | E25: 43907 | F25: 43941 | G25: D - A | H25: =IF(Таблица3[[#This Row],[Denumire grup]]=Ghid!$B$6,"A1 - A10",IF(Таблица3[[#This Row],[Denumire grup]]=Ghid!$B$5,"A11 - A20",IF(Таблица3[[#This Row],[Denumire grup]]=Ghid!$B$7,"B1 - B5",IF(Таблица3[[#This Row],[Denumire grup]]=Ghid!$B$8,"B6 - B15",IF(Таблица3[[#This Row],[Denumire grup]]=Ghid!$B$9,"B16 - B30",IF(Таблица3[[#This Row],[Denumire grup]]=Ghid!$B$10,"C1 - C20","C21 - C30")))))) -> A11 - A20 | I25: 456 | J25: =IF(Таблица3[[#This Row],[Data livrare]]>Таблица3[[#This Row],[Data de receptionate]],Ghid!$D$15,Ghid!$D$16) -> Livrat | K25: Brasov | L25: 45 | M25: =Таблица3[[#This Row],[Pret receptie unitar/RON]]*Таблица3[[#This Row],[Cantitate de produs]] -> 20520 | N25: Transport partener | O25: =Таблица3[[#This Row],[Cantitate de produs]]+20 -> 476 | P25: 10 | Q25: =Таблица3[[#This Row],[Cantitate Total kg]]-Таблица3[[#This Row],[Vandute kg/luna]] -> 466 | R25: =Таблица3[[#This Row],[Vandute kg/luna]]*(Таблица3[[#This Row],[Pret receptie unitar/RON]]+((Таблица3[[#This Row],[Pret receptie unitar/RON]]*25)/100)) -> 562.5 | S25: =Таблица3[[#This Row],[Vandute/RON]]-Таблица3[[#This Row],[Cheltuieli]] -> -19957.5
A26: =A25+1 -> 25 | B26: Manusi M | C26: Materiale constructie | D26: buc | E26: 43969 | F26: 43981 | G26: D - A | H26: =IF(Таблица3[[#This Row],[Denumire grup]]=Ghid!$B$6,"A1 - A10",IF(Таблица3[[#This Row],[Denumire grup]]=Ghid!$B$5,"A11 - A20",IF(Таблица3[[#This Row],[Denumire grup]]=Ghid!$B$7,"B1 - B5",IF(Таблица3[[#This Row],[Denumire grup]]=Ghid!$B$8,"B6 - B15",IF(Таблица3[[#This Row],[Denumire grup]]=Ghid!$B$9,"B16 - B30",IF(Таблица3[[#This Row],[Denumire grup]]=Ghid!$B$10,"C1 - C20","C21 - C30")))))) -> A11 - A20 | I26: 1254 | J26: =IF(Таблица3[[#This Row],[Data livrare]]>Таблица3[[#This Row],[Data de receptionate]],Ghid!$D$15,Ghid!$D$16) -> Livrat | K26: Timisoare | L26: 78 | M26: =Таблица3[[#This Row],[Pret receptie unitar/RON]]*Таблица3[[#This Row],[Cantitate de produs]] -> 97812 | N26: Transport firma | O26: =Таблица3[[#This Row],[Cantitate de produs]]+20 -> 1274 | P26: 45 | Q26: =Таблица3[[#This Row],[Cantitate Total kg]]-Таблица3[[#This Row],[Vandute kg/luna]] -> 1229 | R26: =Таблица3[[#This Row],[Vandute kg/luna]]*(Таблица3[[#This Row],[Pret receptie unitar/RON]]+((Таблица3[[#This Row],[Pret receptie unitar/RON]]*25)/100)) -> 4387.5 | S26: =Таблица3[[#This Row],[Vandute/RON]]-Таблица3[[#This Row],[Cheltuieli]] -> -93424.5
A27: =A26+1 -> 26 | B27: Rodie | C27: Alimente | D27: kg/buc | E27: 44103 | F27: 44134 | G27: D - A | H27: =IF(Таблица3[[#This Row],[Denumire grup]]=Ghid!$B$6,"A1 - A10",IF(Таблица3[[#This Row],[Denumire grup]]=Ghid!$B$5,"A11 - A20",IF(Таблица3[[#This Row],[Denumire grup]]=Ghid!$B$7,"B1 - B5",IF(Таблица3[[#This Row],[Denumire grup]]=Ghid!$B$8,"B6 - B15",IF(Таблица3[[#This Row],[Denumire grup]]=Ghid!$B$9,"B16 - B30",IF(Таблица3[[#This Row],[Denumire grup]]=Ghid!$B$10,"C1 - C20","C21 - C30")))))) -> A1 - A10 | I27: 6365 | J27: =IF(Таблица3[[#This Row],[Data livrare]]>Таблица3[[#This Row],[Data de receptionate]],Ghid!$D$15,Ghid!$D$16) -> Livrat | K27: Alba - Iulia | L27: 96 | M27: =Таблица3[[#This Row],[Pret receptie unitar/RON]]*Таблица3[[#This Row],[Cantitate de produs]] -> 611040 | N27: Transport partener | O27: =Таблица3[[#This Row],[Cantitate de produs]]+20 -> 6385 | P27: 12 | Q27: =Таблица3[[#This Row],[Cantitate Total kg]]-Таблица3[[#This Row],[Vandute kg/luna]] -> 6373 | R27: =Таблица3[[#This Row],[Vandute kg/luna]]*(Таблица3[[#This Row],[Pret receptie unitar/RON]]+((Таблица3[[#This Row],[Pret receptie unitar/RON]]*25)/100)) -> 1440 | S27: =Таблица3[[#This Row],[Vandute/RON]]-Таблица3[[#This Row],[Cheltuieli]] -> -609600
A28: =A27+1 -> 27 | B28: Traversa 120 | C28: Materiale constructie | D28: pachet | E28: 43969 | F28: 44002 | G28: D - A | H28: =IF(Таблица3[[#This Row],[Denumire grup]]=Ghid!$B$6,"A1 - A10",IF(Таблица3[[#This Row],[Denumire grup]]=Ghid!$B$5,"A11 - A20",IF(Таблица3[[#This Row],[Denumire grup]]=Ghid!$B$7,"B1 - B5",IF(Таблица3[[#This Row],[Denumire grup]]=Ghid!$B$8,"B6 - B15",IF(Таблица3[[#This Row],[Denumire grup]]=Ghid!$B$9,"B16 - B30",IF(Таблица3[[#This Row],[Denumire grup]]=Ghid!$B$10,"C1 - C20","C21 - C30")))))) -> A11 - A20 | I28: 5600 | J28: =IF(Таблица3[[#This Row],[Data livrare]]>Таблица3[[#This Row],[Data de receptionate]],Ghid!$D$15,Ghid!$D$16) -> Livrat | K28: Timisoare | L28: 45 | M28: =Таблица3[[#This Row],[Pret receptie unitar/RON]]*Таблица3[[#This Row],[Cantitate de produs]] -> 252000 | N28: Personal fizic | O28: =Таблица3[[#This Row],[Cantitate de produs]]+20 -> 5620 | P28: 12 | Q28: =Таблица3[[#This Row],[Cantitate Total kg]]-Таблица3[[#This Row],[Vandute kg/luna]] -> 5608 | R28: =Таблица3[[#This Row],[Vandute kg/luna]]*(Таблица3[[#This Row],[Pret receptie unitar/RON]]+((Таблица3[[#This Row],[Pret receptie unitar/RON]]*25)/100)) -> 675 | S28: =Таблица3[[#This Row],[Vandute/RON]]-Таблица3[[#This Row],[Cheltuieli]] -> -251325
A29: =A28+1 -> 28 | B29: Vin | C29: Bauturi | D29: buc | E29: 43969 | F29: 44073 | G29: D - C | H29: =IF(Таблица3[[#This Row],[Denumire grup]]=Ghid!$B$6,"A1 - A10",IF(Таблица3[[#This Row],[Denumire grup]]=Ghid!$B$5,"A11 - A20",IF(Таблица3[[#This Row],[Denumire grup]]=Ghid!$B$7,"B1 - B5",IF(Таблица3[[#This Row],[Denumire grup]]=Ghid!$B$8,"B6 - B15",IF(Таблица3[[#This Row],[Denumire grup]]=Ghid!$B$9,"B16 - B30",IF(Таблица3[[#This Row],[Denumire grup]]=Ghid!$B$10,"C1 - C20","C21 - C30")))))) -> C1 - C20 | I29: 1235 | J29: =IF(Таблица3[[#This Row],[Data livrare]]>Таблица3[[#This Row],[Data de receptionate]],Ghid!$D$15,Ghid!$D$16) -> Livrat | K29: Brasov | L29: 50 | M29: =Таблица3[[#This Row],[Pret receptie unitar/RON]]*Таблица3[[#This Row],[Cantitate de produs]] -> 61750 | N29: Personal fizic | O29: =Таблица3[[#This Row],[Cantitate de produs]]+20 -> 1255 | P29: 48 | Q29: =Таблица3[[#This Row],[Cantitate Total kg]]-Таблица3[[#This Row],[Vandute kg/luna]] -> 1207 | R29: =Таблица3[[#This Row],[Vandute kg/luna]]*(Таблица3[[#This Row],[Pret receptie unitar/RON]]+((Таблица3[[#This Row],[Pret receptie unitar/RON]]*25)/100)) -> 3000 | S29: =Таблица3[[#This Row],[Vandute/RON]]-Таблица3[[#This Row],[Cheltuieli]] -> -58750
A30: =A29+1 -> 29 | B30: Vin alb | C30: Bauturi | D30: buc | E30: 44103 | F30: 44140 | G30: D - C | H30: =IF(Таблица3[[#This Row],[Denumire grup]]=Ghid!$B$6,"A1 - A10",IF(Таблица3[[#This Row],[Denumire grup]]=Ghid!$B$5,"A11 - A20",IF(Таблица3[[#This Row],[Denumire grup]]=Ghid!$B$7,"B1 - B5",IF(Таблица3[[#This Row],[Denumire grup]]=Ghid!$B$8,"B6 - B15",IF(Таблица3[[#This Row],[Denumire grup]]=Ghid!$B$9,"B16 - B30",IF(Таблица3[[#This Row],[Denumire grup]]=Ghid!$B$10,"C1 - C20","C21 - C30")))))) -> C1 - C20 | I30: 4569 | J30: =IF(Таблица3[[#This Row],[Data livrare]]>Таблица3[[#This Row],[Data de receptionate]],Ghid!$D$15,Ghid!$D$16) -> Livrat | K30: Timisoare | L30: 16 | M30: =Таблица3[[#This Row],[Pret receptie unitar/RON]]*Таблица3[[#This Row],[Cantitate de produs]] -> 73104 | N30: Personal fizic | O30: =Таблица3[[#This Row],[Cantitate de produs]]+20 -> 4589 | P30: 99 | Q30: =Таблица3[[#This Row],[Cantitate Total kg]]-Таблица3[[#This Row],[Vandute kg/luna]] -> 4490 | R30: =Таблица3[[#This Row],[Vandute kg/luna]]*(Таблица3[[#This Row],[Pret receptie unitar/RON]]+((Таблица3[[#This Row],[Pret receptie unitar/RON]]*25)/100)) -> 1980 | S30: =Таблица3[[#This Row],[Vandute/RON]]-Таблица3[[#This Row],[Cheltuieli]] -> -71124
A31: =A30+1 -> 30 | B31: Ceapa | C31: Alimente | D31: kg/buc | E31: 44344 | F31: 44348 | G31: D - A | H31: =IF(Таблица3[[#This Row],[Denumire grup]]=Ghid!$B$6,"A1 - A10",IF(Таблица3[[#This Row],[Denumire grup]]=Ghid!$B$5,"A11 - A20",IF(Таблица3[[#This Row],[Denumire grup]]=Ghid!$B$7,"B1 - B5",IF(Таблица3[[#This Row],[Denumire grup]]=Ghid!$B$8,"B6 - B15",IF(Таблица3[[#This Row],[Denumire grup]]=Ghid!$B$9,"B16 - B30",IF(Таблица3[[#This Row],[Denumire grup]]=Ghid!$B$10,"C1 - C20","C21 - C30")))))) -> A1 - A10 | I31: 456 | J31: =IF(Таблица3[[#This Row],[Data livrare]]>Таблица3[[#This Row],[Data de receptionate]],Ghid!$D$15,Ghid!$D$16) -> Livrat | K31: Timisoare | L31: 25 | M31: =Таблица3[[#This Row],[Pret receptie unitar/RON]]*Таблица3[[#This Row],[Cantitate de produs]] -> 11400 | N31: Curier | O31: =Таблица3[[#This Row],[Cantitate de produs]]+20 -> 476 | P31: 50 | Q31: =Таблица3[[#This Row],[Cantitate Total kg]]-Таблица3[[#This Row],[Vandute kg/luna]] -> 426 | R31: =Таблица3[[#This Row],[Vandute kg/luna]]*(Таблица3[[#This Row],[Pret receptie unitar/RON]]+((Таблица3[[#This Row],[Pret receptie unitar/RON]]*25)/100)) -> 1562.5 | S31: =Таблица3[[#This Row],[Vandute/RON]]-Таблица3[[#This Row],[Cheltuieli]] -> -9837.5

Sheet MaxMin
A3: Nr.crt | B3: Produs | C3: Region | D3: Data | E3: Ianuarie | F3: Februarie | G3: Martie | H3: Aprilie | I3: Mai | J3: Iunie | K3: Total | L3: Medie valorica
A4: 1 | B4: Bere Negru | C4: Nord - Vest | D4: 43963 | E4: 456 | F4: 789 | G4: 46 | H4: 1258 | I4: 696 | J4: 123 | K4: =Таблица2[[#This Row],[Ianuarie]]+Таблица2[[#This Row],[Februarie]]+Таблица2[[#This Row],[Martie]]+Таблица2[[#This Row],[Aprilie]]+Таблица2[[#This Row],[Mai]] -> 3245 | L4: =ROUND(((Таблица2[[#This Row],[Ianuarie]]+Таблица2[[#This Row],[Februarie]]+Таблица2[[#This Row],[Martie]]+Таблица2[[#This Row],[Aprilie]]+Таблица2[[#This Row],[Mai]]+Таблица2[[#This Row],[Iunie]])/6),2) -> 561.33
A5: 2 | B5: Vitamin C (lichid) 250 | C5: Centru | D5: 43860 | E5: 45 | F5: 1258 | G5: 4569 | H5: 963 | I5: 96 | J5: 458 | K5: =Таблица2[[#This Row],[Ianuarie]]+Таблица2[[#This Row],[Februarie]]+Таблица2[[#This Row],[Martie]]+Таблица2[[#This Row],[Aprilie]]+Таблица2[[#This Row],[Mai]] -> 6931 | L5: =ROUND(((Таблица2[[#This Row],[Ianuarie]]+Таблица2[[#This Row],[Februarie]]+Таблица2[[#This Row],[Martie]]+Таблица2[[#This Row],[Aprilie]]+Таблица2[[#This Row],[Mai]]+Таблица2[[#This Row],[Iunie]])/6),2) -> 1231.5
A6: 3 | B6: Vitamin C | C6: Nord - Est | D6: 43835 | E6: 78 | F6: 565 | G6: 963 | H6: 696 | I6: 966 | J6: 963 | K6: =Таблица2[[#This Row],[Ianuarie]]+Таблица2[[#This Row],[Februarie]]+Таблица2[[#This Row],[Martie]]+Таблица2[[#This Row],[Aprilie]]+Таблица2[[#This Row],[Mai]] -> 3268 | L6: =ROUND(((Таблица2[[#This Row],[Ianuarie]]+Таблица2[[#This Row],[Februarie]]+Таблица2[[#This Row],[Martie]]+Таблица2[[#This Row],[Aprilie]]+Таблица2[[#This Row],[Mai]]+Таблица2[[#This Row],[Iunie]])/6),2) -> 705.17
A7: 4 | B7: Traversa 80 | C7: Sud - Est | D7: 43966 | E7: 36 | F7: 562 | G7: 789 | H7: 365 | I7: 465 | J7: 456 | K7: =Таблица2[[#This Row],[Ianuarie]]+Таблица2[[#This Row],[Februarie]]+Таблица2[[#This Row],[Martie]]+Таблица2[[#This Row],[Aprilie]]+Таблица2[[#This Row],[Mai]] -> 2217 | L7: =ROUND(((Таблица2[[#This Row],[Ianuarie]]+Таблица2[[#This Row],[Februarie]]+Таблица2[[#This Row],[Martie]]+Таблица2[[#This Row],[Aprilie]]+Таблица2[[#This Row],[Mai]]+Таблица2[[#This Row],[Iunie]])/6),2) -> 445.5
A8: 5 | B8: Pungi 5l | C8: Sud - Muntenie | D8: 44002 | E8: 961 | F8: 359 | G8: 4123 | H8: 565 | I8: 2121 | J8: 131 | K8: =Таблица2[[#This Row],[Ianuarie]]+Таблица2[[#This Row],[Februarie]]+Таблица2[[#This Row],[Martie]]+Таблица2[[#This Row],[Aprilie]]+Таблица2[[#This Row],[Mai]] -> 8129 | L8: =ROUND(((Таблица2[[#This Row],[Ianuarie]]+Таблица2[[#This Row],[Februarie]]+Таблица2[[#This Row],[Martie]]+Таблица2[[#This Row],[Aprilie]]+Таблица2[[#This Row],[Mai]]+Таблица2[[#This Row],[Iunie]])/6),2) -> 1376.67
A9: 6 | B9: Vopsea rosu 1l | C9: Bucuresti - Ilfov | D9: 44129 | E9: 11 | F9: 1216 | G9: 1654 | H9: 6332 | I9: 56 | J9: 132 | K9: =Таблица2[[#This Row],[Ianuarie]]+Таблица2[[#This Row],[Februarie]]+Таблица2[[#This Row],[Martie]]+Таблица2[[#This Row],[Aprilie]]+Таблица2[[#This Row],[Mai]] -> 9269 | L9: =ROUND(((Таблица2[[#This Row],[Ianuarie]]+Таблица2[[#This Row],[Februarie]]+Таблица2[[#This Row],[Martie]]+Таблица2[[#This Row],[Aprilie]]+Таблица2[[#This Row],[Mai]]+Таблица2[[#This Row],[Iunie]])/6),2) -> 1566.83
A10: 7 | B10: Bere Desprados | C10: Sud - Vest Oltenie | D10: 30.02.21 | E10: =4+4 -> 8 | F10: 323 | G10: 2121 | H10: 121 | I10: 113 | J10: 161 | K10: =Таблица2[[#This Row],[Ianuarie]]+Таблица2[[#This Row],[Februarie]]+Таблица2[[#This Row],[Martie]]+Таблица2[[#This Row],[Aprilie]]+Таблица2[[#This Row],[Mai]] -> 2686 | L10: =ROUND(((Таблица2[[#This Row],[Ianuarie]]+Таблица2[[#This Row],[Februarie]]+Таблица2[[#This Row],[Martie]]+Таблица2[[#This Row],[Aprilie]]+Таблица2[[#This Row],[Mai]]+Таблица2[[#This Row],[Iunie]])/6),2) -> 474.5
A11: 8 | B11: Hartie proaspat | C11: Nord - Vest | D11: 44270 | E11: 123 | F11: 633 | G11: 221 | H11: 2131 | I11: 2 | J11: 646 | K11: =Таблица2[[#This Row],[Ianuarie]]+Таблица2[[#This Row],[Februarie]]+Таблица2[[#This Row],[Martie]]+Таблица2[[#This Row],[Aprilie]]+Таблица2[[#This Row],[Mai]] -> 3110 | L11: =ROUND(((Таблица2[[#This Row],[Ianuarie]]+Таблица2[[#This Row],[Februarie]]+Таблица2[[#This Row],[Martie]]+Таблица2[[#This Row],[Aprilie]]+Таблица2[[#This Row],[Mai]]+Таблица2[[#This Row],[Iunie]])/6),2) -> 626
A12: 9 | B12: Servetele | C12: Centru | D12: 44301 | E12: 696 | F12: 212 | G12: 963 | H12: 54 | J12: 213 | K12: =Таблица2[[#This Row],[Ianuarie]]+Таблица2[[#This Row],[Februarie]]+Таблица2[[#This Row],[Martie]]+Таблица2[[#This Row],[Aprilie]]+Таблица2[[#This Row],[Mai]] -> 1925 | L12: =ROUND(((Таблица2[[#This Row],[Ianuarie]]+Таблица2[[#This Row],[Februarie]]+Таблица2[[#This Row],[Martie]]+Таблица2[[#This Row],[Aprilie]]+Таблица2[[#This Row],[Mai]]+Таблица2[[#This Row],[Iunie]])/6),2) -> 356.33
A13: 10 | B13: Morcov | C13: Nord - Est | D13: 44301 | E13: 34 | F13: 3321 | G13: 1214 | H13: 512 | I13: 33 | J13: 465 | K13: =Таблица2[[#This Row],[Ianuarie]]+Таблица2[[#This Row],[Februarie]]+Таблица2[[#This Row],[Martie]]+Таблица2[[#This Row],[Aprilie]]+Таблица2[[#This Row],[Mai]] -> 5114 | L13: =ROUND(((Таблица2[[#This Row],[Ianuarie]]+Таблица2[[#This Row],[Februarie]]+Таблица2[[#This Row],[Martie]]+Таблица2[[#This Row],[Aprilie]]+Таблица2[[#This Row],[Mai]]+Таблица2[[#This Row],[Iunie]])/6),2) -> 929.83
A14: 11 | B14: Banane | C14: Sud - Est | D14: 44332 | E14: 1328 | F14: 132 | G14: 212 | H14: 132 | I14: 55 | J14: 322 | K14: =Таблица2[[#This Row],[Ianuarie]]+Таблица2[[#This Row],[Februarie]]+Таблица2[[#This Row],[Martie]]+Таблица2[[#This Row],[Aprilie]]+Таблица2[[#This Row],[Mai]] -> 1859 | L14: =ROUND(((Таблица2[[#This Row],[Ianuarie]]+Таблица2[[#This Row],[Februarie]]+Таблица2[[#This Row],[Martie]]+Таблица2[[#This Row],[Aprilie]]+Таблица2[[#This Row],[Mai]]+Таблица2[[#This Row],[Iunie]])/6),2) -> 363.5
A15: 12 | B15: Salata Verde | C15: Sud - Muntenie | D15: 44332 | E15: 265 | F15: 866 | G15: 32 | H15: 212 | I15: 96 | J15: 133 | K15: =Таблица2[[#This Row],[Ianuarie]]+Таблица2[[#This Row],[Februarie]]+Таблица2[[#This Row],[Martie]]+Таблица2[[#This Row],[Aprilie]]+Таблица2[[#This Row],[Mai]] -> 1471 | L15: =ROUND(((Таблица2[[#This Row],[Ianuarie]]+Таблица2[[#This Row],[Februarie]]+Таблица2[[#This Row],[Martie]]+Таблица2[[#This Row],[Aprilie]]+Таблица2[[#This Row],[Mai]]+Таблица2[[#This Row],[Iunie]])/6),2) -> 267.33
A16: 13 | B16: Traversa 120 | C16: Bucuresti - Ilfov | D16: 44336 | E16: 133 | F16: 3121 | G16: 213 | H16: 449 | I16: 544 | J16: 489 | K16: =Таблица2[[#This Row],[Ianuarie]]+Таблица2[[#This Row],[Februarie]]+Таблица2[[#This Row],[Martie]]+Таблица2[[#This Row],[Aprilie]]+Таблица2[[#This Row],[Mai]] -> 4460 | L16: =ROUND(((Таблица2[[#This Row],[Ianuarie]]+Таблица2[[#This Row],[Februarie]]+Таблица2[[#This Row],[Martie]]+Таблица2[[#This Row],[Aprilie]]+Таблица2[[#This Row],[Mai]]+Таблица2[[#This Row],[Iunie]])/6),2) -> 824.83
A17: 14 | B17: Vin | C17: Sud - Vest Oltenie | D17: 44337 | E17: 996 | F17: 213 | G17: 45 | H17: 211 | I17: 12 | J17: 963 | K17: =Таблица2[[#This Row],[Ianuarie]]+Таблица2[[#This Row],[Februarie]]+Таблица2[[#This Row],[Martie]]+Таблица2[[#This Row],[Aprilie]]+Таблица2[[#This Row],[Mai]] -> 1477 | L17: =ROUND(((Таблица2[[#This Row],[Ianuarie]]+Таблица2[[#This Row],[Februarie]]+Таблица2[[#This Row],[Martie]]+Таблица2[[#This Row],[Aprilie]]+Таблица2[[#This Row],[Mai]]+Таблица2[[#This Row],[Iunie]])/6),2) -> 406.67
A18: 15 | B18: Vin alb | C18: Nord - Vest | D18: 44341 | E18: 654 | F18: 963 | G18: 896 | H18: 3123 | I18: 213 | J18: 132 | K18: =Таблица2[[#This Row],[Ianuarie]]+Таблица2[[#This Row],[Februarie]]+Таблица2[[#This Row],[Martie]]+Таблица2[[#This Row],[Aprilie]]+Таблица2[[#This Row],[Mai]] -> 5849 | L18: =ROUND(((Таблица2[[#This Row],[Ianuarie]]+Таблица2[[#This Row],[Februarie]]+Таблица2[[#This Row],[Martie]]+Таблица2[[#This Row],[Aprilie]]+Таблица2[[#This Row],[Mai]]+Таблица2[[#This Row],[Iunie]])/6),2) -> 996.83
A19: 16 | B19: Ceapa | C19: Centru | D19: 44341 | E19: 13 | F19: 362 | G19: 4121 | H19: 2330 | I19: 49 | J19: 798 | K19: =Таблица2[[#This Row],[Ianuarie]]+Таблица2[[#This Row],[Februarie]]+Таблица2[[#This Row],[Martie]]+Таблица2[[#This Row],[Aprilie]]+Таблица2[[#This Row],[Mai]] -> 6875 | L19: =ROUND(((Таблица2[[#This Row],[Ianuarie]]+Таблица2[[#This Row],[Februarie]]+Таблица2[[#This Row],[Martie]]+Таблица2[[#This Row],[Aprilie]]+Таблица2[[#This Row],[Mai]]+Таблица2[[#This Row],[Iunie]])/6),2) -> 1278.83
A20: 17 | B20: Ventilator cu picior | C20: Nord - Est | D20: 44337 | E20: 1423 | F20: 489 | G20: 963 | H20: 1235 | I20: 21 | J20: 151 | K20: =Таблица2[[#This Row],[Ianuarie]]+Таблица2[[#This Row],[Februarie]]+Таблица2[[#This Row],[Martie]]+Таблица2[[#This Row],[Aprilie]]+Таблица2[[#This Row],[Mai]] -> 4131 | L20: =ROUND(((Таблица2[[#This Row],[Ianuarie]]+Таблица2[[#This Row],[Februarie]]+Таблица2[[#This Row],[Martie]]+Таблица2[[#This Row],[Aprilie]]+Таблица2[[#This Row],[Mai]]+Таблица2[[#This Row],[Iunie]])/6),2) -> 713.67
A21: 18 | B21: Radiatr electric | C21: Sud - Est | D21: 44341 | E21: 985 | F21: 6321 | G21: 2335 | H21: 897 | I21: 213 | J21: 21 | K21: =Таблица2[[#This Row],[Ianuarie]]+Таблица2[[#This Row],[Februarie]]+Таблица2[[#This Row],[Martie]]+Таблица2[[#This Row],[Aprilie]]+Таблица2[[#This Row],[Mai]] -> 10751 | L21: =ROUND(((Таблица2[[#This Row],[Ianuarie]]+Таблица2[[#This Row],[Februarie]]+Таблица2[[#This Row],[Martie]]+Таблица2[[#This Row],[Aprilie]]+Таблица2[[#This Row],[Mai]]+Таблица2[[#This Row],[Iunie]])/6),2) -> 1795.33
A22: 19 | B22: Masina de spalat | C22: Sud - Muntenie | D22: 44341 | E22: 4523 | F22: 885 | G22: 451 | H22: 454 | I22: 498 | J22: 113 | K22: =Таблица2[[#This Row],[Ianuarie]]+Таблица2[[#This Row],[Februarie]]+Таблица2[[#This Row],[Martie]]+Таблица2[[#This Row],[Aprilie]]+Таблица2[[#This Row],[Mai]] -> 6811 | L22: =ROUND(((Таблица2[[#This Row],[Ianuarie]]+Таблица2[[#This Row],[Februarie]]+Таблица2[[#This Row],[Martie]]+Таблица2[[#This Row],[Aprilie]]+Таблица2[[#This Row],[Mai]]+Таблица2[[#This Row],[Iunie]])/6),2) -> 1154
A23: 20 | B23: Cana filtrate | C23: Sud - Vest Oltenie | D23: 44270 | E23: 456 | F23: 795 | G23: 58 | H23: 122 | I23: 465 | J23: 896 | K23: =Таблица2[[#This Row],[Ianuarie]]+Таблица2[[#This Row],[Februarie]]+Таблица2[[#This Row],[Martie]]+Таблица2[[#This Row],[Aprilie]]+Таблица2[[#This Row],[Mai]] -> 1896 | L23: =ROUND(((Таблица2[[#This Row],[Ianuarie]]+Таблица2[[#This Row],[Februarie]]+Таблица2[[#This Row],[Martie]]+Таблица2[[#This Row],[Aprilie]]+Таблица2[[#This Row],[Mai]]+Таблица2[[#This Row],[Iunie]])/6),2) -> 465.33
A24: 21 | B24: Masina electrica | C24: Nord - Vest | D24: 44301 | E24: 328 | F24: 646 | G24: 26 | H24: 565 | I24: 232 | J24: 1654 | K24: =Таблица2[[#This Row],[Ianuarie]]+Таблица2[[#This Row],[Februarie]]+Таблица2[[#This Row],[Martie]]+Таблица2[[#This Row],[Aprilie]]+Таблица2[[#This Row],[Mai]] -> 1797 | L24: =ROUND(((Таблица2[[#This Row],[Ianuarie]]+Таблица2[[#This Row],[Februarie]]+Таблица2[[#This Row],[Martie]]+Таблица2[[#This Row],[Aprilie]]+Таблица2[[#This Row],[Mai]]+Таблица2[[#This Row],[Iunie]])/6),2) -> 575.17
... A33: 30 | B33: Sapun Lichid | C33: Nord - Vest | D33: 44301 | E33: 465 | F33: 89 | G33: 154 | H33: 455 | I33: 221 | J33: 5654 | K33: =Таблица2[[#This Row],[Ianuarie]]+Таблица2[[#This Row],[Februarie]]+Таблица2[[#This Row],[Martie]]+Таблица2[[#This Row],[Aprilie]]+Таблица2[[#This Row],[Mai]] -> 1384 | L33: =ROUND(((Таблица2[[#This Row],[Ianuarie]]+Таблица2[[#This Row],[Februarie]]+Таблица2[[#This Row],[Martie]]+Таблица2[[#This Row],[Aprilie]]+Таблица2[[#This Row],[Mai]]+Таблица2[[#This Row],[Iunie]])/6),2) -> 1173
A34: Total | E34: =SUM(E4:E33) -> 19212 | F34: =SUM(F4:F33) -> 30311 | G34: =SUM(G4:G33) -> 39019 | H34: =SUM(H4:H33) -> 31988 | I34: =SUM(I4:I33) -> 12277 | J34: =SUM(J4:J33) -> 24138 | K34: =SUM(K4:K33) -> 132807 | L34: =ROUND(((Таблица2[[#This Row],[Ianuarie]]+Таблица2[[#This Row],[Februarie]]+Таблица2[[#This Row],[Martie]]+Таблица2[[#This Row],[Aprilie]]+Таблица2[[#This Row],[Mai]]+Таблица2[[#This Row],[Iunie]])/6),2) -> 26157.5

Sheet Cantitate
D4: Produs | E4: Cantitate venite | F4: Data | G4: Pret unitar/RON | H4: Cantitate kg | I4: Vandute kg | J4: Rest | K4: Profit | L4: Total
C5: Ian | D5: Pungi 5l | E5: 465 | G5: 89 | H5: =Таблица11[[#This Row],[Cantitate venite]]*20 -> 9300 | I5: 211 | J5: =Таблица11[[#This Row],[Cantitate kg]]-Таблица11[[#This Row],[Vandute kg]] -> 9089 | K5: =Таблица11[[#This Row],[Pret unitar/RON]]*Таблица11[[#This Row],[Vandute kg]] -> 18779 | L5: =SUM(I5:I8) -> 1785
D6: morcov | E6: 13 | G6: 2 | H6: =Таблица11[[#This Row],[Cantitate venite]]*20 -> 260 | I6: 240 | J6: =Таблица11[[#This Row],[Cantitate kg]]-Таблица11[[#This Row],[Vandute kg]] -> 20 | K6: =Таблица11[[#This Row],[Pret unitar/RON]]*Таблица11[[#This Row],[Vandute kg]] -> 480
D7: Traversa 80 | E7: 316 | G7: 150 | H7: =Таблица11[[#This Row],[Cantitate venite]]*20 -> 6320 | I7: 13 | J7: =Таблица11[[#This Row],[Cantitate kg]]-Таблица11[[#This Row],[Vandute kg]] -> 6307 | K7: =Таблица11[[#This Row],[Pret unitar/RON]]*Таблица11[[#This Row],[Vandute kg]] -> 1950
D8: Vitamin C (lichid) 250 | E8: 791 | G8: 150 | H8: =Таблица11[[#This Row],[Cantitate venite]]*20 -> 15820 | I8: 1321 | J8: =Таблица11[[#This Row],[Cantitate kg]]-Таблица11[[#This Row],[Vandute kg]] -> 14499 | K8: =Таблица11[[#This Row],[Pret unitar/RON]]*Таблица11[[#This Row],[Vandute kg]] -> 198150
C9: Feb | D9: Vin | E9: 598 | G9: 96 | H9: =Таблица11[[#This Row],[Cantitate venite]]*20 -> 11960 | I9: 7895 | J9: =Таблица11[[#This Row],[Cantitate kg]]-Таблица11[[#This Row],[Vandute kg]] -> 4065 | K9: =Таблица11[[#This Row],[Pret unitar/RON]]*Таблица11[[#This Row],[Vandute kg]] -> 757920 | L9: =SUM(I9:I15) -> 20563
D10: Radiatr electric | E10: 56 | G10: 250 | H10: =Таблица11[[#This Row],[Cantitate venite]]*20 -> 1120 | I10: 465 | J10: =Таблица11[[#This Row],[Cantitate kg]]-Таблица11[[#This Row],[Vandute kg]] -> 655 | K10: =Таблица11[[#This Row],[Pret unitar/RON]]*Таблица11[[#This Row],[Vandute kg]] -> 116250
D11: Hartie proaspat | E11: 132 | G11: 120 | H11: =Таблица11[[#This Row],[Cantitate venite]]*20 -> 2640 | I11: 132 | J11: =Таблица11[[#This Row],[Cantitate kg]]-Таблица11[[#This Row],[Vandute kg]] -> 2508 | K11: =Таблица11[[#This Row],[Pret unitar/RON]]*Таблица11[[#This Row],[Vandute kg]] -> 15840
D12: Traversa 80 | E12: 446 | G12: 145 | H12: =Таблица11[[#This Row],[Cantitate venite]]*20 -> 8920 | I12: 1321 | J12: =Таблица11[[#This Row],[Cantitate kg]]-Таблица11[[#This Row],[Vandute kg]] -> 7599 | K12: =Таблица11[[#This Row],[Pret unitar/RON]]*Таблица11[[#This Row],[Vandute kg]] -> 191545
D13: Vitamin C (lichid) 250 | E13: 596 | G13: 55 | H13: =Таблица11[[#This Row],[Cantitate venite]]*20 -> 11920 | I13: 5465 | J13: =Таблица11[[#This Row],[Cantitate kg]]-Таблица11[[#This Row],[Vandute kg]] -> 6455 | K13: =Таблица11[[#This Row],[Pret unitar/RON]]*Таблица11[[#This Row],[Vandute kg]] -> 300575
D14: Vitamin C | E14: 1651 | G14: 150 | H14: =Таблица11[[#This Row],[Cantitate venite]]*20 -> 33020 | I14: 4645 | J14: =Таблица11[[#This Row],[Cantitate kg]]-Таблица11[[#This Row],[Vandute kg]] -> 28375 | K14: =Таблица11[[#This Row],[Pret unitar/RON]]*Таблица11[[#This Row],[Vandute kg]] -> 696750
D15: Pungi 5l | E15: 32 | G15: 45 | H15: =Таблица11[[#This Row],[Cantitate venite]]*20 -> 640 | I15: 640 | J15: =Таблица11[[#This Row],[Cantitate kg]]-Таблица11[[#This Row],[Vandute kg]] -> 0 | K15: =Таблица11[[#This Row],[Pret unitar/RON]]*Таблица11[[#This Row],[Vandute kg]] -> 28800
C16: Mar | D16: Vitamin C | E16: 6898 | G16: 78 | H16: =Таблица11[[#This Row],[Cantitate venite]]*20 -> 137960 | I16: 5452 | J16: =Таблица11[[#This Row],[Cantitate kg]]-Таблица11[[#This Row],[Vandute kg]] -> 132508 | K16: =Таблица11[[#This Row],[Pret unitar/RON]]*Таблица11[[#This Row],[Vandute kg]] -> 425256 | L16: =SUM(I16:I21) -> 17873
D17: Morcov | E17: 639 | G17: 45 | H17: =Таблица11[[#This Row],[Cantitate venite]]*20 -> 12780 | I17: 2121 | J17: =Таблица11[[#This Row],[Cantitate kg]]-Таблица11[[#This Row],[Vandute kg]] -> 10659 | K17: =Таблица11[[#This Row],[Pret unitar/RON]]*Таблица11[[#This Row],[Vandute kg]] -> 95445
D18: Vitamin C (lichid) 250 | E18: 1133 | G18: 155 | H18: =Таблица11[[#This Row],[Cantitate venite]]*20 -> 22660 | I18: 9852 | J18: =Таблица11[[#This Row],[Cantitate kg]]-Таблица11[[#This Row],[Vandute kg]] -> 12808 | K18: =Таблица11[[#This Row],[Pret unitar/RON]]*Таблица11[[#This Row],[Vandute kg]] -> 1527060
D19: Banane | E19: 449 | G19: 2 | H19: =Таблица11[[#This Row],[Cantitate venite]]*20 -> 8980 | I19: 231 | J19: =Таблица11[[#This Row],[Cantitate kg]]-Таблица11[[#This Row],[Vandute kg]] -> 8749 | K19: =Таблица11[[#This Row],[Pret unitar/RON]]*Таблица11[[#This Row],[Vandute kg]] -> 462
D20: Salata Verde | E20: 465 | G20: 1 | H20: =Таблица11[[#This Row],[Cantitate venite]]*20 -> 9300 | I20: 213 | J20: =Таблица11[[#This Row],[Cantitate kg]]-Таблица11[[#This Row],[Vandute kg]] -> 9087 | K20: =Таблица11[[#This Row],[Pret unitar/RON]]*Таблица11[[#This Row],[Vandute kg]] -> 213
D21: Cana filtrate | E21: 546 | G21: 200 | H21: =Таблица11[[#This Row],[Cantitate venite]]*20 -> 10920 | I21: 4 | J21: =Таблица11[[#This Row],[Cantitate kg]]-Таблица11[[#This Row],[Vandute kg]] -> 10916 | K21: =Таблица11[[#This Row],[Pret unitar/RON]]*Таблица11[[#This Row],[Vandute kg]] -> 800
C22: Apr | D22: Traversa 80 | E22: 494 | G22: 250 | H22: =Таблица11[[#This Row],[Cantitate venite]]*20 -> 9880 | I22: 2132 | J22: =Таблица11[[#This Row],[Cantitate kg]]-Таблица11[[#This Row],[Vandute kg]] -> 7748 | K22: =Таблица11[[#This Row],[Pret unitar/RON]]*Таблица11[[#This Row],[Vandute kg]] -> 533000 | L22: =SUM(I22:I28) -> 6127
D23: Bere Negru | E23: 998 | G23: 3 | H23: =Таблица11[[#This Row],[Cantitate venite]]*20 -> 19960 | I23: 121 | J23: =Таблица11[[#This Row],[Cantitate kg]]-Таблица11[[#This Row],[Vandute kg]] -> 19839 | K23: =Таблица11[[#This Row],[Pret unitar/RON]]*Таблица11[[#This Row],[Vandute kg]] -> 363
D24: Masina de spalat | E24: 987 | G24: 400 | H24: =Таблица11[[#This Row],[Cantitate venite]]*20 -> 19740 | I24: 2313 | J24: =Таблица11[[#This Row],[Cantitate kg]]-Таблица11[[#This Row],[Vandute kg]] -> 17427 | K24: =Таблица11[[#This Row],[Pret unitar/RON]]*Таблица11[[#This Row],[Vandute kg]] -> 925200
D25: Servetele | E25: 5646 | G25: 0.5 | H25: =Таблица11[[#This Row],[Cantitate venite]]*20 -> 112920 | I25: 213 | J25: =Таблица11[[#This Row],[Cantitate kg]]-Таблица11[[#This Row],[Vandute kg]] -> 112707 | K25: =Таблица11[[#This Row],[Pret unitar/RON]]*Таблица11[[#This Row],[Vandute kg]] -> 106.5
D26: Vin alb | E26: 131 | G26: 12 | H26: =Таблица11[[#This Row],[Cantitate venite]]*20 -> 2620 | I26: 6 | J26: =Таблица11[[#This Row],[Cantitate kg]]-Таблица11[[#This Row],[Vandute kg]] -> 2614 | K26: =Таблица11[[#This Row],[Pret unitar/RON]]*Таблица11[[#This Row],[Vandute kg]] -> 72
D27: Ceapa | E27: 466 | G27: 2 | H27: =Таблица11[[#This Row],[Cantitate venite]]*20 -> 9320 | I27: 698 | J27: =Таблица11[[#This Row],[Cantitate kg]]-Таблица11[[#This Row],[Vandute kg]] -> 8622 | K27: =Таблица11[[#This Row],[Pret unitar/RON]]*Таблица11[[#This Row],[Vandute kg]] -> 1396
D28: Bere Desprados | E28: 987 | G28: 2.5 | H28: =Таблица11[[#This Row],[Cantitate venite]]*20 -> 19740 | I28: 644 | J28: =Таблица11[[#This Row],[Cantitate kg]]-Таблица11[[#This Row],[Vandute kg]] -> 19096 | K28: =Таблица11[[#This Row],[Pret unitar/RON]]*Таблица11[[#This Row],[Vandute kg]] -> 1610
C29: Mai | D29: Hartie proaspat | E29: 984 | G29: 10 | H29: =Таблица11[[#This Row],[Cantitate venite]]*20 -> 19680 | I29: 6546 | J29: =Таблица11[[#This Row],[Cantitate kg]]-Таблица11[[#This Row],[Vandute kg]] -> 13134 | K29: =Таблица11[[#This Row],[Pret unitar/RON]]*Таблица11[[#This Row],[Vandute kg]] -> 65460 | L29: =SUM(I29:I32) -> 12564
D30: Masina electrica | E30: 9879 | G30: 80 | H30: =Таблица11[[#This Row],[Cantitate venite]]*20 -> 197580 | I30: 465 | J30: =Таблица11[[#This Row],[Cantitate kg]]-Таблица11[[#This Row],[Vandute kg]] -> 197115 | K30: =Таблица11[[#This Row],[Pret unitar/RON]]*Таблица11[[#This Row],[Vandute kg]] -> 37200
D31: Hartie proaspat | E31: 899 | G31: 2 | H31: =Таблица11[[#This Row],[Cantitate venite]]*20 -> 17980 | I31: 4656 | J31: =Таблица11[[#This Row],[Cantitate kg]]-Таблица11[[#This Row],[Vandute kg]] -> 13324 | K31: =Таблица11[[#This Row],[Pret unitar/RON]]*Таблица11[[#This Row],[Vandute kg]] -> 9312
D32: Morcov | E32: 654 | G32: 3 | H32: =Таблица11[[#This Row],[Cantitate venite]]*20 -> 13080 | I32: 897 | J32: =Таблица11[[#This Row],[Cantitate kg]]-Таблица11[[#This Row],[Vandute kg]] -> 12183 | K32: =Таблица11[[#This Row],[Pret unitar/RON]]*Таблица11[[#This Row],[Vandute kg]] -> 2691
C33: Iun | D33: Pungi 5l | E33: 654 | G33: 45 | H33: =Таблица11[[#This Row],[Cantitate venite]]*20 -> 13080 | I33: 9875 | J33: =Таблица11[[#This Row],[Cantitate kg]]-Таблица11[[#This Row],[Vandute kg]] -> 3205 | K33: =Таблица11[[#This Row],[Pret unitar/RON]]*Таблица11[[#This Row],[Vandute kg]] -> 444375 | L33: =SUM(I33:I40) -> 179658
D34: Ceapa | E34: 5646 | G34: 2 | H34: =Таблица11[[#This Row],[Cantitate venite]]*20 -> 112920 | I34: 112910 | J34: =Таблица11[[#This Row],[Cantitate kg]]-Таблица11[[#This Row],[Vandute kg]] -> 10 | K34: =Таблица11[[#This Row],[Pret unitar/RON]]*Таблица11[[#This Row],[Vandute kg]] -> 225820
D35: Vitamin C (lichid) 250 | E35: 646 | G35: 150 | H35: =Таблица11[[#This Row],[Cantitate venite]]*20 -> 12920 | I35: 4654 | J35: =Таблица11[[#This Row],[Cantitate kg]]-Таблица11[[#This Row],[Vandute kg]] -> 8266 | K35: =Таблица11[[#This Row],[Pret unitar/RON]]*Таблица11[[#This Row],[Vandute kg]] -> 698100
D36: Banane | E36: 654 | G36: 3 | H36: =Таблица11[[#This Row],[Cantitate venite]]*20 -> 13080 | I36: 465 | J36: =Таблица11[[#This Row],[Cantitate kg]]-Таблица11[[#This Row],[Vandute kg]] -> 12615 | K36: =Таблица11[[#This Row],[Pret unitar/RON]]*Таблица11[[#This Row],[Vandute kg]] -> 1395
D37: Masina electrica | E37: 979 | G37: 123 | H37: =Таблица11[[#This Row],[Cantitate venite]]*20 -> 19580 | I37: 19575 | J37: =Таблица11[[#This Row],[Cantitate kg]]-Таблица11[[#This Row],[Vandute kg]] -> 5 | K37: =Таблица11[[#This Row],[Pret unitar/RON]]*Таблица11[[#This Row],[Vandute kg]] -> 2407725
D38: Traversa 120 | E38: 499 | G38: 250 | H38: =Таблица11[[#This Row],[Cantitate venite]]*20 -> 9980 | I38: 9970 | J38: =Таблица11[[#This Row],[Cantitate kg]]-Таблица11[[#This Row],[Vandute kg]] -> 10 | K38: =Таблица11[[#This Row],[Pret unitar/RON]]*Таблица11[[#This Row],[Vandute kg]] -> 2492500
D39: Traversa 80 | E39: 979 | G39: 80 | H39: =Таблица11[[#This Row],[Cantitate venite]]*20 -> 19580 | I39: 19570 | J39: =Таблица11[[#This Row],[Cantitate kg]]-Таблица11[[#This Row],[Vandute kg]] -> 10 | K39: =Таблица11[[#This Row],[Pret unitar/RON]]*Таблица11[[#This Row],[Vandute kg]] -> 1565600
